Workbook

Sheet Sheet1
A1: \multirow{15}{*}{1} & \multirow{5}{*}{RB\%}
A2: & 100 & | B2: =Sheet2!A1 -> 36.6678 | C2: & | D2: =Sheet2!B1 -> -18.83565 | E2: & | F2: =Sheet2!C1 -> -80.55118 | G2: & | H2: =Sheet2!D1 -> -132.6027 | I2: & | J2: =Sheet2!E1 -> 38.39688 | K2: & | L2: =Sheet2!F1 -> 4.188828 | M2: \\
A3: & & 200 & | B3: =Sheet2!A2 -> 28.5569 | C3: & | D3: =Sheet2!B2 -> -11.46045 | E3: & | F3: =Sheet2!C2 -> -56.53052 | G3: & | H3: =Sheet2!D2 -> -93.6532 | I3: & | J3: =Sheet2!E2 -> 27.21732 | K3: & | L3: =Sheet2!F2 -> 1.752466 | M3: \\
A4: & & 300 & | B4: =Sheet2!A3 -> 18.1501 | C4: & | D4: =Sheet2!B3 -> -7.1503 | E4: & | F4: =Sheet2!C3 -> -35.3897 | G4: & | H4: =Sheet2!D3 -> -60.8472 | I4: & | J4: =Sheet2!E3 -> 16.83264 | K4: & | L4: =Sheet2!F3 -> 1.235614 | M4: \\
A5: & & 500 & | B5: =Sheet2!A4 -> 8.5856 | C5: & | D5: =Sheet2!B4 -> -3.76705 | E5: & | F5: =Sheet2!C4 -> -16.3023 | G5: & | H5: =Sheet2!D4 -> -27.9448 | I5: & | J5: =Sheet2!E4 -> 7.53302 | K5: & | L5: =Sheet2!F4 -> 0.74383 | M5: \\
A6: & & 1,000 & | B6: =Sheet2!A5 -> 2.9836 | C6: & | D6: =Sheet2!B5 -> -1.582 | E6: & | F6: =Sheet2!C5 -> -6.6723 | G6: & | H6: =Sheet2!D5 -> -11.4565 | I6: & | J6: =Sheet2!E5 -> 3.16388 | K6: & | L6: =Sheet2!F5 -> 0.384162 | M6: \\ \cmidrule{2-9}
A7: & \multirow{5}{*}{RMSE}
A8: & 100 & | B8: =Sheet2!A6 -> 0.09346979 | C8: & | D8: =Sheet2!B6 -> 0.13437297 | E8: & | F8: =Sheet2!C6 -> 0.5264426 | G8: & | H8: =Sheet2!D6 -> 0.22447905 | I8: & | J8: =Sheet2!E6 -> 0.31874602 | K8: & | L8: =Sheet2!F6 -> 0.4969056 | M8: \\
A9: & & 200 & | B9: =Sheet2!A7 -> 0.06813823 | C9: & | D9: =Sheet2!B7 -> 0.09137639 | E9: & | F9: =Sheet2!C7 -> 0.4395111 | G9: & | H9: =Sheet2!D7 -> 0.18395215 | I9: & | J9: =Sheet2!E7 -> 0.26306922 | K9: & | L9: =Sheet2!F7 -> 0.316974 | M9: \\
A10: & & 300 & | B10: =Sheet2!A8 -> 0.05567757 | C10: & | D10: =Sheet2!B8 -> 0.07318536 | E10: & | F10: =Sheet2!C8 -> 0.3352349 | G10: & | H10: =Sheet2!D8 -> 0.14149604 | I10: & | J10: =Sheet2!E8 -> 0.20050013 | K10: & | L10: =Sheet2!F8 -> 0.2484756 | M10: \\
A11: & & 500 & | B11: =Sheet2!A9 -> 0.03870537 | C11: & | D11: =Sheet2!B9 -> 0.05390841 | E11: & | F11: =Sheet2!C9 -> 0.2154132 | G11: & | H11: =Sheet2!D9 -> 0.09395357 | I11: & | J11: =Sheet2!E9 -> 0.12978137 | K11: & | L11: =Sheet2!F9 -> 0.1902221 | M11: \\
A12: & & 1,000 & | B12: =Sheet2!A10 -> 0.02070541 | C12: & | D12: =Sheet2!B10 -> 0.03470074 | E12: & | F12: =Sheet2!C10 -> 0.1130222 | G12: & | H12: =Sheet2!D10 -> 0.04854086 | I12: & | J12: =Sheet2!E10 -> 0.06946074 | K12: & | L12: =Sheet2!F10 -> 0.135225 | M12: \\ \cmidrule{2-9}
A13: & \multirow{5}{*}{CR95\%}
A14: & 100 & | B14: =Sheet2!A11 -> 0.851 | C14: & | D14: =Sheet2!B11 -> 0.792 | E14: & | F14: =Sheet2!C11 -> 0.652 | G14: & | H14: =Sheet2!D11 -> 0.681 | I14: & | J14: =Sheet2!E11 -> 0.671 | K14: & | L14: =Sheet2!F11 -> 0.935 | M14: \\
A15: & & 200 & | B15: =Sheet2!A12 -> 0.865 | C15: & | D15: =Sheet2!B12 -> 0.835 | E15: & | F15: =Sheet2!C12 -> 0.732 | G15: & | H15: =Sheet2!D12 -> 0.752 | I15: & | J15: =Sheet2!E12 -> 0.741 | K15: & | L15: =Sheet2!F12 -> 0.938 | M15: \\
A16: & & 300 & | B16: =Sheet2!A13 -> 0.877 | C16: & | D16: =Sheet2!B13 -> 0.886 | E16: & | F16: =Sheet2!C13 -> 0.81 | G16: & | H16: =Sheet2!D13 -> 0.823 | I16: & | J16: =Sheet2!E13 -> 0.823 | K16: & | L16: =Sheet2!F13 -> 0.947 | M16: \\
A17: & & 500 & | B17: =Sheet2!A14 -> 0.903 | C17: & | D17: =Sheet2!B14 -> 0.92 | E17: & | F17: =Sheet2!C14 -> 0.9 | G17: & | H17: =Sheet2!D14 -> 0.908 | I17: & | J17: =Sheet2!E14 -> 0.908 | K17: & | L17: =Sheet2!F14 -> 0.95 | M17: \\
A18: & & 1,000 & | B18: =Sheet2!A15 -> 0.946 | C18: & | D18: =Sheet2!B15 -> 0.943 | E18: & | F18: =Sheet2!C15 -> 0.925 | G18: & | H18: =Sheet2!D15 -> 0.935 | I18: & | J18: =Sheet2!E15 -> 0.936 | K18: & | L18: =Sheet2!F15 -> 0.94 | M18: \\ \hline
A19: \multirow{15}{*}{2} & \multirow{5}{*}{RB\%}
A20: & 100 & | B20: =Sheet2!A16 -> 0 | C20: & | D20: =Sheet2!B16 -> 0 | E20: & | F20: =Sheet2!C16 -> 0 | G20: & | H20: =Sheet2!D16 -> 0 | I20: & | J20: $-$ | K20: & | L20: =Sheet2!F16 -> 0 | M20: \\
A21: & & 200 & | B21: =Sheet2!A17 -> 0 | C21: & | D21: =Sheet2!B17 -> 0 | E21: & | F21: =Sheet2!C17 -> 0 | G21: & | H21: =Sheet2!D17 -> 0 | I21: & | J21: $-$ | K21: & | L21: =Sheet2!F17 -> 0 | M21: \\
A22: & & 300 & | B22: =Sheet2!A18 -> 0 | C22: & | D22: =Sheet2!B18 -> 0 | E22: & | F22: =Sheet2!C18 -> 0 | G22: & | H22: =Sheet2!D18 -> 0 | I22: & | J22: $-$ | K22: & | L22: =Sheet2!F18 -> 0 | M22: \\
A23: & & 500 & | B23: =Sheet2!A19 -> 0 | C23: & | D23: =Sheet2!B19 -> 0 | E23: & | F23: =Sheet2!C19 -> 0 | G23: & | H23: =Sheet2!D19 -> 0 | I23: & | J23: $-$ | K23: & | L23: =Sheet2!F19 -> 0 | M23: \\
A24: & & 1,000 & | B24: =Sheet2!A20 -> 0 | C24: & | D24: =Sheet2!B20 -> 0 | E24: & | F24: =Sheet2!C20 -> 0 | G24: & | H24: =Sheet2!D20 -> 0 | I24: & | J24: $-$ | K24: & | L24: =Sheet2!F20 -> 0 | M24: \\ \cmidrule{2-9}
A25: & \multirow{5}{*}{RMSE}
A26: & 100 & | B26: =Sheet2!A21 -> 0 | C26: & | D26: =Sheet2!B21 -> 0 | E26: & | F26: =Sheet2!C21 -> 0 | G26: & | H26: =Sheet2!D21 -> 0 | I26: & | J26: $-$ | K26: & | L26: =Sheet2!F21 -> 0 | M26: \\
A27: & & 200 & | B27: =Sheet2!A22 -> 0 | C27: & | D27: =Sheet2!B22 -> 0 | E27: & | F27: =Sheet2!C22 -> 0 | G27: & | H27: =Sheet2!D22 -> 0 | I27: & | J27: $-$ | K27: & | L27: =Sheet2!F22 -> 0 | M27: \\
A28: & & 300 & | B28: =Sheet2!A23 -> 0 | C28: & | D28: =Sheet2!B23 -> 0 | E28: & | F28: =Sheet2!C23 -> 0 | G28: & | H28: =Sheet2!D23 -> 0 | I28: & | J28: $-$ | K28: & | L28: =Sheet2!F23 -> 0 | M28: \\
A29: & & 500 & | B29: =Sheet2!A24 -> 0 | C29: & | D29: =Sheet2!B24 -> 0 | E29: & | F29: =Sheet2!C24 -> 0 | G29: & | H29: =Sheet2!D24 -> 0 | I29: & | J29: $-$ | K29: & | L29: =Sheet2!F24 -> 0 | M29: \\
A30: & & 1,000 & | B30: =Sheet2!A25 -> 0 | C30: & | D30: =Sheet2!B25 -> 0 | E30: & | F30: =Sheet2!C25 -> 0 | G30: & | H30: =Sheet2!D25 -> 0 | I30: & | J30: $-$ | K30: & | L30: =Sheet2!F25 -> 0 | M30: \\ \cmidrule{2-9}
A31: & \multirow{5}{*}{CR95\%}
A32: & 100 & | B32: =Sheet2!A26 -> 0 | C32: & | D32: =Sheet2!B26 -> 0 | E32: & | F32: =Sheet2!C26 -> 0 | G32: & | H32: =Sheet2!D26 -> 0 | I32: & | J32: $-$ | K32: & | L32: =Sheet2!F26 -> 0 | M32: \\
A33: & & 200 & | B33: =Sheet2!A27 -> 0 | C33: & | D33: =Sheet2!B27 -> 0 | E33: & | F33: =Sheet2!C27 -> 0 | G33: & | H33: =Sheet2!D27 -> 0 | I33: & | J33: $-$ | K33: & | L33: =Sheet2!F27 -> 0 | M33: \\
A34: & & 300 & | B34: =Sheet2!A28 -> 0 | C34: & | D34: =Sheet2!B28 -> 0 | E34: & | F34: =Sheet2!C28 -> 0 | G34: & | H34: =Sheet2!D28 -> 0 | I34: & | J34: $-$ | K34: & | L34: =Sheet2!F28 -> 0 | M34: \\
A35: & & 500 & | B35: =Sheet2!A29 -> 0 | C35: & | D35: =Sheet2!B29 -> 0 | E35: & | F35: =Sheet2!C29 -> 0 | G35: & | H35: =Sheet2!D29 -> 0 | I35: & | J35: $-$ | K35: & | L35: =Sheet2!F29 -> 0 | M35: \\
A36: & & 1,000 & | B36: =Sheet2!A30 -> 0 | C36: & | D36: =Sheet2!B30 -> 0 | E36: & | F36: =Sheet2!C30 -> 0 | G36: & | H36: =Sheet2!D30 -> 0 | I36: & | J36: $-$ | K36: & | L36: =Sheet2!F30 -> 0 | M36: \\ \hline
A37: \multirow{15}{*}{3} & \multirow{5}{*}{RB\%}
A38: & 100 & | B38: =Sheet2!A31 -> 0 | C38: & | D38: =Sheet2!B31 -> 0 | E38: & | F38: =Sheet2!C31 -> 0 | G38: & | H38: $-$ | I38: & | J38: =Sheet2!E31 -> 0 | K38: & | L38: =Sheet2!F31 -> 0 | M38: \\
A39: & & 200 & | B39: =Sheet2!A32 -> 0 | C39: & | D39: =Sheet2!B32 -> 0 | E39: & | F39: =Sheet2!C32 -> 0 | G39: & | H39: $-$ | I39: & | J39: =Sheet2!E32 -> 0 | K39: & | L39: =Sheet2!F32 -> 0 | M39: \\
A40: & & 300 & | B40: =Sheet2!A33 -> 0 | C40: & | D40: =Sheet2!B33 -> 0 | E40: & | F40: =Sheet2!C33 -> 0 | G40: & | H40: $-$ | I40: & | J40: =Sheet2!E33 -> 0 | K40: & | L40: =Sheet2!F33 -> 0 | M40: \\
...

Sheet Sheet2
A1: 36.6678 | B1: -18.83565 | C1: -80.55118 | D1: -132.6027 | E1: 38.39688 | F1: 4.188828
A2: 28.5569 | B2: -11.46045 | C2: -56.53052 | D2: -93.6532 | E2: 27.21732 | F2: 1.752466
A3: 18.1501 | B3: -7.1503 | C3: -35.3897 | D3: -60.8472 | E3: 16.83264 | F3: 1.235614
A4: 8.5856 | B4: -3.76705 | C4: -16.3023 | D4: -27.9448 | E4: 7.53302 | F4: 0.74383
A5: 2.9836 | B5: -1.582 | C5: -6.6723 | D5: -11.4565 | E5: 3.16388 | F5: 0.384162
A6: 0.09346979 | B6: 0.13437297 | C6: 0.5264426 | D6: 0.22447905 | E6: 0.31874602 | F6: 0.4969056
A7: 0.06813823 | B7: 0.09137639 | C7: 0.4395111 | D7: 0.18395215 | E7: 0.26306922 | F7: 0.316974
A8: 0.05567757 | B8: 0.07318536 | C8: 0.3352349 | D8: 0.14149604 | E8: 0.20050013 | F8: 0.2484756
A9: 0.03870537 | B9: 0.05390841 | C9: 0.2154132 | D9: 0.09395357 | E9: 0.12978137 | F9: 0.1902221
A10: 0.02070541 | B10: 0.03470074 | C10: 0.1130222 | D10: 0.04854086 | E10: 0.06946074 | F10: 0.135225
A11: 0.851 | B11: 0.792 | C11: 0.652 | D11: 0.681 | E11: 0.671 | F11: 0.935
A12: 0.865 | B12: 0.835 | C12: 0.732 | D12: 0.752 | E12: 0.741 | F12: 0.938
... A15: 0.946 | B15: 0.943 | C15: 0.925 | D15: 0.935 | E15: 0.936 | F15: 0.94
A46: 61.7665 | B46: -8.6504 | C46: -109.40805 | F46: 2.092684
A47: 57.1196 | B47: -11.86245 | C47: -91.51382 | F47: 0.701326
A48: 47.6353 | B48: -10.55395 | C48: -76.15852 | F48: 0.568938
A49: 26.1779 | B49: -7.27155 | C49: -40.4665 | F49: 0.351068
A50: 14.1306 | B50: -5.0239 | C50: -22.09578 | F50: 0.106686
A51: 0.11873281 | B51: 0.13280831 | C51: 0.7036664 | F51: 0.4233246
A52: 0.12363444 | B52: 0.11572502 | C52: 0.6547386 | F52: 0.2869326
A53: 0.09986039 | B53: 0.09053843 | C53: 0.6055131 | F53: 0.2259001
A54: 0.07612989 | B54: 0.06940335 | C54: 0.4417937 | F54: 0.1720061
A55: 0.05684323 | B55: 0.05306063 | C55: 0.3270179 | F55: 0.1236638
A56: 0.752 | B56: 0.797 | C56: 0.615 | F56: 0.931
A57: 0.707 | B57: 0.794 | C57: 0.67 | F57: 0.942
... A60: 0.887 | B60: 0.905 | C60: 0.877 | F60: 0.94
